<mujocoinclude>

  <body name="base_link" gravcomp="1" pos="0 0 0.02" quat="1 0 0 0">
    <inertial
      pos="-0.000648 -0.000166 0.084487"
      quat="1 0 0 0"
      mass="1.697"
      diaginertia="0.004622 0.004495 0.002079"
    />
    <geom class="visual" mesh="base_link" material="white" />
    <geom class="collision" mesh="base_link_c" />
    <body
      name="shoulder_link"
      gravcomp="1"
      pos="0 0 0.15643"
      quat="-3.67321e-06 1 0 0"
    >
      <inertial
        pos="-2.3e-05 -0.010364 -0.07336"
        quat="0.707051 0.0451246 -0.0453544 0.704263"
        mass="1.3773"
        diaginertia="0.00488868 0.00457 0.00135132"
      />
      <joint class="infiniteJoints" name="joint_1" armature="0.0000015" />
      <geom class="visual" mesh="shoulder_link" material="white" />
      <geom class="collision" mesh="shoulder_link_c" />
      <body
        name="half_arm_1_link"
        gravcomp="1"
        pos="0 0.005375 -0.12838"
        quat="0.707105 0.707108 0 0"
      >
        <inertial
          pos="-4.4e-05 -0.09958 -0.013278"
          quat="0.482348 0.516286 -0.516862 0.483366"
          mass="1.1636"
          diaginertia="0.0113017 0.011088 0.00102532"
        />
        <joint
          class="limitedJoints"
          name="joint_2"
          range="-2.41 2.41"
          armature="0.0000015"
        />
        <geom class="visual" mesh="half_arm_1_link" material="white" />
        <geom class="collision" mesh="half_arm_1_link_c" />
        <body
          name="half_arm_2_link"
          gravcomp="1"
          pos="0 -0.21038 -0.006375"
          quat="0.707105 -0.707108 0 0"
        >
          <inertial
            pos="-4.4e-05 -0.006641 -0.117892"
            quat="0.706144 0.0213722 -0.0209128 0.707437"
            mass="1.1636"
            diaginertia="0.0111633 0.010932 0.00100671"
          />
          <joint class="infiniteJoints" name="joint_3" armature="0.0000015" />
          <geom class="visual" mesh="half_arm_2_link" material="white" />
          <geom class="collision" mesh="half_arm_2_link_c" />
          <body
            name="forearm_link"
            gravcomp="1"
            pos="0 0.006375 -0.21038"
            quat="0.707105 0.707108 0 0"
          >
            <inertial
              pos="-1.8e-05 -0.075478 -0.015006"
              quat="0.483678 0.515961 -0.515859 0.483455"
              mass="0.9302"
              diaginertia="0.00834839 0.008147 0.000598606"
            />
            <joint
              class="limitedJoints"
              name="joint_4"
              range="-2.66 2.66"
              armature="0.0000015"
            />
            <geom class="visual" mesh="forearm_link" material="white" />
            <geom class="collision" mesh="forearm_link_c" />
            <body
              name="spherical_wrist_1_link"
              gravcomp="1"
              pos="0 -0.20843 -0.006375"
              quat="0.707105 -0.707108 0 0"
            >
              <inertial
                pos="1e-06 -0.009432 -0.063883"
                quat="0.703558 0.0707492 -0.0707492 0.703558"
                mass="0.6781"
                diaginertia="0.00165901 0.001596 0.000346988"
              />
              <joint
                class="infiniteJoints"
                name="joint_5"
                armature="0.000001928"
              />
              <geom
                class="visual"
                mesh="spherical_wrist_1_link"
                material="white"
              />
              <geom class="collision" mesh="spherical_wrist_1_link_c" />
              <body
                name="spherical_wrist_2_link"
                gravcomp="1"
                pos="0 0.00017505 -0.10593"
                quat="0.707105 0.707108 0 0"
              >
                <inertial
                  pos="1e-06 -0.045483 -0.00965"
                  quat="0.44426 0.550121 -0.550121 0.44426"
                  mass="0.6781"
                  diaginertia="0.00170087 0.001641 0.00035013"
                />
                <joint
                  class="limitedJoints"
                  name="joint_6"
                  range="-2.23 2.23"
                  armature="0.000001928"
                />
                <geom
                  class="visual"
                  mesh="spherical_wrist_2_link"
                  material="white"
                />
                <geom class="collision" mesh="spherical_wrist_2_link_c" />
                <body
                  name="bracelet_link"
                  gravcomp="1"
                  pos="0 -0.10593 -0.00017505"
                  quat="0.707105 -0.707108 0 0"
                >
                  <camera
                    name="wrist_camera"
                    pos="0.0 -0.056 -0.058"
                    fovy="58"
                    mode="fixed"
                    resolution="1920 1080"
                    quat="0.0 0.0 0.0 1.0"
                  />
                  <site
                    name="wrist_camera_optical_frame"
                    pos="0.0 -0.056 -0.058"
                    quat="0.0 0.0 1.0 0.0"
                  />
                  <inertial
                    pos="-9.3e-05 0.000132 -0.022905"
                    quat="-0.0368025 0.719402 -0.0444884 0.69219"
                    mass="0.364"
                    diaginertia="0.00024027 0.000222769 0.000213961"
                  />
                  <joint
                    class="infiniteJoints"
                    name="joint_7"
                    armature="0.000001928"
                  />
                  <geom
                    class="visual"
                    mesh="bracelet_with_vision_link"
                    material="white"
                  />
                  <geom
                    class="collision"
                    mesh="bracelet_with_vision_link_c"
                  />
                  <body childclass="2f85">
                    <!-- site for end effector's f/t sensor right at the base of the robotiq gripper -->
                    <site
                      name="fts"
                      size="0.01"
                      pos="0.0 0.0 -0.0615"
                      quat="0 0.0 1.0 0.0"
                    />
                    <!-- Right-hand side 4-bar linkage -->
                    <body
                      name="robotiq_85_base_link"
                      gravcomp="1"
                      pos="0 0 -0.0615"
                      quat="0 -0.707 0.707 0"
                    >
                      <inertial
                        mass="0.777441"
                        pos="0 -2.70394e-05 0.0354675"
                        quat="1 -0.00152849 0 0"
                        diaginertia="0.000260285 0.000225381 0.000152708"
                      />
                      <geom
                        class="visual"
                        mesh="robotiq_85_base"
                        material="black"
                      />
                      <geom class="collision" mesh="robotiq_85_base" />
                      <site
                        name="pinch"
                        pos="0 0 0.145"
                        type="sphere"
                        group="5"
                        rgba="0.9 0.9 0.9 1"
                        size="0.005"
                      />
                      <!-- Right-hand side 4-bar linkage -->
                      <body
                        name="robotiq_85_right_knuckle_link"
                        gravcomp="1"
                        pos="0 0.0306011 0.054904"
                      >
                        <inertial
                          mass="0.00899563"
                          pos="2.96931e-12 0.0177547 0.00107314"
                          quat="0.681301 0.732003 0 0"
                          diaginertia="1.72352e-06 1.60906e-06 3.22006e-07"
                        />
                        <joint
                          name="robotiq_85_right_knuckle_joint"
                          class="knuckle_link"
                        />
                        <geom
                          class="visual"
                          mesh="robotiq_85_knuckle_link"
                          material="gray"
                        />
                        <geom
                          class="collision"
                          mesh="robotiq_85_knuckle_link"
                        />
                        <body
                          name="robotiq_85_right_finger_link"
                          gravcomp="1"
                          pos="0 0.0315 -0.0041"
                        >
                          <inertial
                            mass="0.0140974"
                            pos="0 0.00301209 0.0232175"
                            quat="0.705636 -0.0455904 0.0455904 0.705636"
                            diaginertia="4.16206e-06 3.52216e-06 8.88131e-07"
                          />
                          <joint
                            name="robotiq_85_right_finger_joint"
                            class="finger_link"
                          />
                          <geom
                            class="visual"
                            mesh="robotiq_85_finger_link"
                            material="black"
                          />
                          <geom
                            class="collision"
                            mesh="robotiq_85_finger_link"
                          />
                        </body>
                      </body>
                      <body
                        name="robotiq_85_right_inner_knuckle_link"
                        gravcomp="1"
                        pos="0 0.0132 0.0609"
                      >
                        <inertial
                          mass="0.0221642"
                          pos="-8.65005e-09 0.0181624 0.0212658"
                          quat="0.663403 -0.244737 0.244737 0.663403"
                          diaginertia="8.96853e-06 6.71733e-06 2.63931e-06"
                        />
                        <joint
                          name="robotiq_85_right_inner_knuckle_joint"
                          class="inner_knuckle_link"
                        />
                        <geom
                          class="visual"
                          mesh="robotiq_85_inner_knuckle_link"
                          material="black"
                        />
                        <geom
                          class="collision"
                          mesh="robotiq_85_inner_knuckle_link"
                        />
                        <body
                          name="robotiq_85_right_finger_tip_link"
                          gravcomp="1"
                          pos="0 0.055 0.0375"
                        >
                          <inertial
                            mass="0.0125222"
                            pos="0 -0.011046 0.0124786"
                            quat="1 0.1664 0 0"
                            diaginertia="2.67415e-06 2.4559e-06 6.02031e-07"
                          />
                          <joint
                            name="robotiq_85_right_finger_tip_joint"
                            class="finger_tip_link"
                          />
                          <geom
                            class="visual"
                            mesh="robotiq_85_finger_tip_link"
                            material="black"
                          />
                          <geom
                            class="collision"
                            mesh="robotiq_85_finger_tip_link"
                          />
                          <body name="right_pad" pos="0 -0.0189 0.01352">
                            <geom class="pad_box1" name="right_pad1" />
                            <geom class="pad_box2" name="right_pad2" />
                            <inertial
                              mass="0.0035"
                              pos="0 -0.0025 0.0185"
                              quat="0.707107 0 0 0.707107"
                              diaginertia="4.73958e-07 3.64583e-07 1.23958e-07"
                            />
                            <geom class="visual" mesh="robotiq_85_pad" />
                            <body name="right_silicone_pad">
                              <geom
                                class="visual"
                                mesh="robotiq_85_silicone_pad"
                                material="black"
                              />
                            </body>
                            <!--                              TODO uncomment to enable RAFTI fingers -->
<!--                            <body-->
<!--                              name="right_rafti_finger_link"-->
<!--                              pos="0 0 0.01"-->
<!--                              quat="0 0 0 1"-->
<!--                            >-->
<!--                              <inertial-->
<!--                                mass="0.005"-->
<!--                                pos="0 0 0"-->
<!--                                diaginertia="8.96853e-06 6.71733e-06 2.63931e-06"-->
<!--                              />-->
<!--                              <geom-->
<!--                                class="visual"-->
<!--                                mesh="rafti_finger"-->
<!--                                material="black"-->
<!--                              />-->
<!--                              <geom-->
<!--                                class="collision"-->
<!--                                mesh="rafti_finger_collision_1"-->
<!--                                condim="6"-->
<!--                              />-->
<!--                              <geom-->
<!--                                class="collision"-->
<!--                                mesh="rafti_finger_collision_2"-->
<!--                                condim="6"-->
<!--                              />-->
<!--                              <geom-->
<!--                                class="collision"-->
<!--                                mesh="rafti_finger_collision_3"-->
<!--                                condim="6"-->
<!--                              />-->
<!--                              <geom-->
<!--                                class="collision"-->
<!--                                mesh="rafti_finger_collision_4"-->
<!--                                condim="6"-->
<!--                              />-->
<!--                            </body>-->
                          </body>
                        </body>
                      </body>
                      <body
                        name="calibration_tool"
                        gravcomp="1"
                        pos="0 0 0.169"
                        quat="-0.7071 0 0 0.7071">
<!--                        <site name="calibration_tool"/>-->
                        <geom
                          class="visual"
                          mesh="calibration_tool"
                          material="gray"
                        />
                        <geom
                          class="collision"
                          mesh="calibration_tool_collision_0"
                        />
                        <geom
                          class="collision"
                          mesh="calibration_tool_collision_1"
                        />
                        <geom
                          class="collision"
                          mesh="calibration_tool_collision_2"
                        />
                        <body name="april_tag_0" pos="0.08625 -0.04925 -0.01" quat="0 0 0 1">
                          <geom
                                  type="box"
                                  size="0.031875 0.031875 0.0001"
                                  rgba="1 1 1 1"
                                  material="ar_marker_0"/>
                          <site name="april_tag_0"/>
                        </body>
                        <body name="april_tag_1" pos="-0.08625 -0.04925 -0.01" quat="0 0 0 1">
                          <geom
                                  type="box"
                                  size="0.031875 0.031875 0.0001"
                                  rgba="1 1 1 1"
                                  material="ar_marker_1"/>
                          <site name="april_tag_1"/>
                        </body>
                        <body name="april_tag_2" pos="0.0 -0.18125 -0.01" quat="0 0 0 1">
                          <geom
                                  type="box"
                                  size="0.031875 0.031875 0.0001"
                                  rgba="1 1 1 1"
                                  material="ar_marker_2"/>
                          <site name="april_tag_2"/>
                        </body>
                      </body>
                      <!-- Left-hand side 4-bar linkage -->
                      <body
                        name="robotiq_85_left_knuckle_link"
                        gravcomp="1"
                        pos="0 -0.0306011 0.054904"
                        quat="0 0 0 1"
                      >
                        <inertial
                          mass="0.00899563"
                          pos="0 0.0177547 0.00107314"
                          quat="0.681301 0.732003 0 0"
                          diaginertia="1.72352e-06 1.60906e-06 3.22006e-07"
                        />
                        <joint
                          name="robotiq_85_left_knuckle_joint"
                          class="knuckle_link"
                        />
                        <geom
                          class="visual"
                          mesh="robotiq_85_knuckle_link"
                          material="gray"
                        />
                        <geom
                          class="collision"
                          mesh="robotiq_85_knuckle_link"
                        />
                        <body
                          name="robotiq_85_left_finger_link"
                          gravcomp="1"
                          pos="0 0.0315 -0.0041"
                        >
                          <inertial
                            mass="0.0140974"
                            pos="0 0.00301209 0.0232175"
                            quat="0.705636 -0.0455904 0.0455904 0.705636"
                            diaginertia="4.16206e-06 3.52216e-06 8.88131e-07"
                          />
                          <joint
                            name="robotiq_85_left_finger_joint"
                            class="finger_link"
                          />
                          <geom
                            class="visual"
                            mesh="robotiq_85_finger_link"
                            material="black"
                          />
                          <geom
                            class="collision"
                            mesh="robotiq_85_finger_link"
                          />
                        </body>
                      </body>
                      <body
                        name="robotiq_85_left_inner_knuckle_link"
                        gravcomp="1"
                        pos="0 -0.0132 0.0609"
                        quat="0 0 0 1"
                      >
                        <inertial
                          mass="0.0221642"
                          pos="-8.65005e-09 0.0181624 0.0212658"
                          quat="0.663403 -0.244737 0.244737 0.663403"
                          diaginertia="8.96853e-06 6.71733e-06 2.63931e-06"
                        />
                        <joint
                          name="robotiq_85_left_inner_knuckle_joint"
                          class="inner_knuckle_link"
                        />
                        <geom
                          class="visual"
                          mesh="robotiq_85_inner_knuckle_link"
                          material="black"
                        />
                        <geom
                          class="collision"
                          mesh="robotiq_85_inner_knuckle_link"
                        />
                        <body
                          name="robotiq_85_left_finger_tip_link"
                          gravcomp="1"
                          pos="0 0.055 0.0375"
                        >
                          <inertial
                            mass="0.0125222"
                            pos="0 -0.011046 0.0124786"
                            quat="1 0.1664 0 0"
                            diaginertia="2.67415e-06 2.4559e-06 6.02031e-07"
                          />
                          <joint
                            name="robotiq_85_left_finger_tip_joint"
                            class="finger_tip_link"
                          />
                          <geom
                            class="visual"
                            mesh="robotiq_85_finger_tip_link"
                            material="black"
                          />
                          <geom
                            class="collision"
                            mesh="robotiq_85_finger_tip_link"
                          />
                          <body name="left_pad" pos="0 -0.0189 0.01352">
                            <geom class="pad_box1" name="left_pad1" />
                            <geom class="pad_box2" name="left_pad2" />
                            <inertial
                              mass="0.0035"
                              pos="0 -0.0025 0.0185"
                              quat="1 0 0 1"
                              diaginertia="4.73958e-07 3.64583e-07 1.23958e-07"
                            />
                            <geom class="visual" mesh="robotiq_85_pad" />
                            <body name="left_silicone_pad">
                              <geom
                                class="visual"
                                mesh="robotiq_85_silicone_pad"
                                material="black"
                              />
                            </body>
                            <!--                              TODO uncomment to enable RAFTI fingers -->
<!--                            <body-->
<!--                              name="left_rafti_finger_link"-->
<!--                              pos="0 0 0.01"-->
<!--                              quat="0 0 0 1"-->
<!--                            >-->
<!--                              <inertial mass="0.005" pos="0 0 0" />-->
<!--                              <geom-->
<!--                                class="visual"-->
<!--                                mesh="rafti_finger"-->
<!--                                material="black"-->
<!--                              />-->
<!--                              <geom-->
<!--                                class="collision"-->
<!--                                mesh="rafti_finger_collision_1"-->
<!--                                condim="6"-->
<!--                              />-->
<!--                              <geom-->
<!--                                class="collision"-->
<!--                                mesh="rafti_finger_collision_2"-->
<!--                                condim="6"-->
<!--                              />-->
<!--                              <geom-->
<!--                                class="collision"-->
<!--                                mesh="rafti_finger_collision_3"-->
<!--                                condim="6"-->
<!--                              />-->
<!--                              <geom-->
<!--                                class="collision"-->
<!--                                mesh="rafti_finger_collision_4"-->
<!--                                condim="6"-->
<!--                              />-->
<!--                            </body>-->
                          </body>
                        </body>
                      </body>
                    </body>
                  </body>
                </body>
              </body>
            </body>
          </body>
        </body>
      </body>
    </body>
  </body>

</mujocoinclude>
